2024-11-12 22:36:47,605 ERROR: Exception on /edit_profile [GET] [in /home/sololobo/microblog/.venv/lib/python3.10/site-packages/flask/app.py:1414]
Traceback (most recent call last):
  File "/home/sololobo/microblog/.venv/lib/python3.10/site-packages/flask/app.py", line 2190, in wsgi_app
    response = self.full_dispatch_request()
  File "/home/sololobo/microblog/.venv/lib/python3.10/site-packages/flask/app.py", line 1486, in full_dispatch_request
    rv = self.handle_user_exception(e)
  File "/home/sololobo/microblog/.venv/lib/python3.10/site-packages/flask/app.py", line 1484, in full_dispatch_request
    rv = self.dispatch_request()
  File "/home/sololobo/microblog/.venv/lib/python3.10/site-packages/flask/app.py", line 1469, in dispatch_request
    return self.ensure_sync(self.view_functions[rule.endpoint])(**view_args)
  File "/home/sololobo/microblog/.venv/lib/python3.10/site-packages/flask_login/utils.py", line 290, in decorated_view
    return current_app.ensure_sync(func)(*args, **kwargs)
  File "/home/sololobo/microblog/app/routes.py", line 123, in edit_profile
    form = EditProfileForm()
  File "/home/sololobo/microblog/.venv/lib/python3.10/site-packages/wtforms/form.py", line 208, in __call__
    return type.__call__(cls, *args, **kwargs)
TypeError: EditProfileForm.__init__() missing 1 required positional argument: 'original_username'
2024-11-12 22:44:34,914 INFO: Microblog startup [in /home/sololobo/microblog/app/__init__.py:45]
2024-11-12 22:44:42,826 ERROR: Exception on /edit_profile [GET] [in /home/sololobo/microblog/.venv/lib/python3.10/site-packages/flask/app.py:1414]
Traceback (most recent call last):
  File "/home/sololobo/microblog/.venv/lib/python3.10/site-packages/flask/app.py", line 2190, in wsgi_app
    response = self.full_dispatch_request()
  File "/home/sololobo/microblog/.venv/lib/python3.10/site-packages/flask/app.py", line 1486, in full_dispatch_request
    rv = self.handle_user_exception(e)
  File "/home/sololobo/microblog/.venv/lib/python3.10/site-packages/flask/app.py", line 1484, in full_dispatch_request
    rv = self.dispatch_request()
  File "/home/sololobo/microblog/.venv/lib/python3.10/site-packages/flask/app.py", line 1469, in dispatch_request
    return self.ensure_sync(self.view_functions[rule.endpoint])(**view_args)
  File "/home/sololobo/microblog/.venv/lib/python3.10/site-packages/flask_login/utils.py", line 290, in decorated_view
    return current_app.ensure_sync(func)(*args, **kwargs)
  File "/home/sololobo/microblog/app/routes.py", line 123, in edit_profile
    form = EditProfileForm()
  File "/home/sololobo/microblog/.venv/lib/python3.10/site-packages/wtforms/form.py", line 208, in __call__
    return type.__call__(cls, *args, **kwargs)
TypeError: EditProfileForm.__init__() missing 1 required positional argument: 'original_username'
2024-11-12 22:54:18,908 INFO: Microblog startup [in /home/sololobo/microblog/app/__init__.py:45]
2024-11-13 15:01:32,953 INFO: Microblog startup [in /home/sololobo/microblog/app/__init__.py:47]
2024-11-13 15:01:34,764 ERROR: Exception on / [GET] [in /home/sololobo/microblog/.venv/lib/python3.10/site-packages/flask/app.py:1414]
Traceback (most recent call last):
  File "/home/sololobo/microblog/.venv/lib/python3.10/site-packages/flask/app.py", line 2190, in wsgi_app
    response = self.full_dispatch_request()
  File "/home/sololobo/microblog/.venv/lib/python3.10/site-packages/flask/app.py", line 1486, in full_dispatch_request
    rv = self.handle_user_exception(e)
  File "/home/sololobo/microblog/.venv/lib/python3.10/site-packages/flask/app.py", line 1484, in full_dispatch_request
    rv = self.dispatch_request()
  File "/home/sololobo/microblog/.venv/lib/python3.10/site-packages/flask/app.py", line 1469, in dispatch_request
    return self.ensure_sync(self.view_functions[rule.endpoint])(**view_args)
  File "/home/sololobo/microblog/.venv/lib/python3.10/site-packages/flask_login/utils.py", line 290, in decorated_view
    return current_app.ensure_sync(func)(*args, **kwargs)
  File "/home/sololobo/microblog/app/routes.py", line 45, in index
    return render_template('index.html', title='Home', form=form,
  File "/home/sololobo/microblog/.venv/lib/python3.10/site-packages/flask/templating.py", line 151, in render_template
    return _render(app, template, context)
  File "/home/sololobo/microblog/.venv/lib/python3.10/site-packages/flask/templating.py", line 132, in _render
    rv = template.render(context)
  File "/home/sololobo/microblog/.venv/lib/python3.10/site-packages/jinja2/environment.py", line 1304, in render
    self.environment.handle_exception()
  File "/home/sololobo/microblog/.venv/lib/python3.10/site-packages/jinja2/environment.py", line 939, in handle_exception
    raise rewrite_traceback_stack(source=source)
  File "/home/sololobo/microblog/app/templates/index.html", line 2, in top-level template code
    {% import "bootstrap_wtf.html" as wtf %}
  File "/home/sololobo/microblog/app/templates/base.html", line 65, in top-level template code
    {{ moment.include_moment() }}
  File "/home/sololobo/microblog/.venv/lib/python3.10/site-packages/jinja2/environment.py", line 487, in getattr
    return getattr(obj, attribute)
jinja2.exceptions.UndefinedError: 'moment' is undefined
2024-11-13 15:02:32,239 INFO: Microblog startup [in /home/sololobo/microblog/app/__init__.py:47]
2024-11-13 15:02:36,455 ERROR: Exception on / [GET] [in /home/sololobo/microblog/.venv/lib/python3.10/site-packages/flask/app.py:1414]
Traceback (most recent call last):
  File "/home/sololobo/microblog/.venv/lib/python3.10/site-packages/flask/app.py", line 2190, in wsgi_app
    response = self.full_dispatch_request()
  File "/home/sololobo/microblog/.venv/lib/python3.10/site-packages/flask/app.py", line 1486, in full_dispatch_request
    rv = self.handle_user_exception(e)
  File "/home/sololobo/microblog/.venv/lib/python3.10/site-packages/flask/app.py", line 1484, in full_dispatch_request
    rv = self.dispatch_request()
  File "/home/sololobo/microblog/.venv/lib/python3.10/site-packages/flask/app.py", line 1469, in dispatch_request
    return self.ensure_sync(self.view_functions[rule.endpoint])(**view_args)
  File "/home/sololobo/microblog/.venv/lib/python3.10/site-packages/flask_login/utils.py", line 290, in decorated_view
    return current_app.ensure_sync(func)(*args, **kwargs)
  File "/home/sololobo/microblog/app/routes.py", line 45, in index
    return render_template('index.html', title='Home', form=form,
  File "/home/sololobo/microblog/.venv/lib/python3.10/site-packages/flask/templating.py", line 151, in render_template
    return _render(app, template, context)
  File "/home/sololobo/microblog/.venv/lib/python3.10/site-packages/flask/templating.py", line 132, in _render
    rv = template.render(context)
  File "/home/sololobo/microblog/.venv/lib/python3.10/site-packages/jinja2/environment.py", line 1304, in render
    self.environment.handle_exception()
  File "/home/sololobo/microblog/.venv/lib/python3.10/site-packages/jinja2/environment.py", line 939, in handle_exception
    raise rewrite_traceback_stack(source=source)
  File "/home/sololobo/microblog/app/templates/index.html", line 2, in top-level template code
    {% import "bootstrap_wtf.html" as wtf %}
  File "/home/sololobo/microblog/app/templates/base.html", line 65, in top-level template code
    {{ moment.include_moment() }}
  File "/home/sololobo/microblog/.venv/lib/python3.10/site-packages/jinja2/environment.py", line 487, in getattr
    return getattr(obj, attribute)
jinja2.exceptions.UndefinedError: 'moment' is undefined
2024-11-13 15:03:46,283 INFO: Microblog startup [in /home/sololobo/microblog/app/__init__.py:47]
2024-11-13 15:21:21,278 INFO: Microblog startup [in /home/sololobo/microblog/app/__init__.py:47]
2024-11-13 15:23:03,066 INFO: Microblog startup [in /home/sololobo/microblog/app/__init__.py:47]
2024-11-21 00:07:37,304 INFO: Microblog startup [in /home/sololobo/microblog/app/__init__.py:55]
2024-11-21 00:11:23,770 INFO: Microblog startup [in /home/sololobo/microblog/app/__init__.py:56]
