2024-10-14 21:23:14,686 ERROR: Exception on /edit_profile [GET] [in /home/sololobo/microblog/.venv/lib/python3.10/site-packages/flask/app.py:1414]
Traceback (most recent call last):
  File "/home/sololobo/microblog/.venv/lib/python3.10/site-packages/flask/app.py", line 2190, in wsgi_app
    response = self.full_dispatch_request()
  File "/home/sololobo/microblog/.venv/lib/python3.10/site-packages/flask/app.py", line 1486, in full_dispatch_request
    rv = self.handle_user_exception(e)
  File "/home/sololobo/microblog/.venv/lib/python3.10/site-packages/flask/app.py", line 1484, in full_dispatch_request
    rv = self.dispatch_request()
  File "/home/sololobo/microblog/.venv/lib/python3.10/site-packages/flask/app.py", line 1469, in dispatch_request
    return self.ensure_sync(self.view_functions[rule.endpoint])(**view_args)
  File "/home/sololobo/microblog/.venv/lib/python3.10/site-packages/flask_login/utils.py", line 290, in decorated_view
    return current_app.ensure_sync(func)(*args, **kwargs)
  File "/home/sololobo/microblog/app/routes.py", line 120, in edit_profile
    form = EditProfileForm()
  File "/home/sololobo/microblog/.venv/lib/python3.10/site-packages/wtforms/form.py", line 208, in __call__
    return type.__call__(cls, *args, **kwargs)
TypeError: EditProfileForm.__init__() missing 1 required positional argument: 'original_username'
2024-10-15 16:46:36,333 INFO: Microblog startup [in /home/sololobo/microblog/app/__init__.py:62]
2024-10-15 17:25:04,204 INFO: Microblog startup [in /home/sololobo/microblog/app/__init__.py:62]
2024-10-15 17:25:17,860 ERROR: Exception on /edit_profile [GET] [in /home/sololobo/microblog/.venv/lib/python3.10/site-packages/flask/app.py:1414]
Traceback (most recent call last):
  File "/home/sololobo/microblog/.venv/lib/python3.10/site-packages/flask/app.py", line 2190, in wsgi_app
    response = self.full_dispatch_request()
  File "/home/sololobo/microblog/.venv/lib/python3.10/site-packages/flask/app.py", line 1486, in full_dispatch_request
    rv = self.handle_user_exception(e)
  File "/home/sololobo/microblog/.venv/lib/python3.10/site-packages/flask/app.py", line 1484, in full_dispatch_request
    rv = self.dispatch_request()
  File "/home/sololobo/microblog/.venv/lib/python3.10/site-packages/flask/app.py", line 1469, in dispatch_request
    return self.ensure_sync(self.view_functions[rule.endpoint])(**view_args)
  File "/home/sololobo/microblog/.venv/lib/python3.10/site-packages/flask_login/utils.py", line 290, in decorated_view
    return current_app.ensure_sync(func)(*args, **kwargs)
  File "/home/sololobo/microblog/app/routes.py", line 128, in edit_profile
    form = EditProfileForm()
  File "/home/sololobo/microblog/.venv/lib/python3.10/site-packages/wtforms/form.py", line 208, in __call__
    return type.__call__(cls, *args, **kwargs)
TypeError: EditProfileForm.__init__() missing 1 required positional argument: 'original_username'
2024-10-15 18:08:18,688 INFO: Microblog startup [in /home/sololobo/microblog/app/__init__.py:62]
2024-11-04 20:48:23,195 INFO: Microblog startup [in /home/sololobo/microblog/app/__init__.py:55]
2024-11-04 20:48:55,345 ERROR: Exception on /reset_password_request [POST] [in /home/sololobo/microblog/.venv/lib/python3.10/site-packages/flask/app.py:1414]
Traceback (most recent call last):
  File "/home/sololobo/microblog/.venv/lib/python3.10/site-packages/flask/app.py", line 2190, in wsgi_app
    response = self.full_dispatch_request()
  File "/home/sololobo/microblog/.venv/lib/python3.10/site-packages/flask/app.py", line 1486, in full_dispatch_request
    rv = self.handle_user_exception(e)
  File "/home/sololobo/microblog/.venv/lib/python3.10/site-packages/flask/app.py", line 1484, in full_dispatch_request
    rv = self.dispatch_request()
  File "/home/sololobo/microblog/.venv/lib/python3.10/site-packages/flask/app.py", line 1469, in dispatch_request
    return self.ensure_sync(self.view_functions[rule.endpoint])(**view_args)
  File "/home/sololobo/microblog/app/routes.py", line 214, in reset_password_request
    send_password_reset_email(user)
  File "/home/sololobo/microblog/app/email.py", line 14, in send_password_reset_email
    token = user.get_reset_password_token()
AttributeError: 'User' object has no attribute 'get_reset_password_token'
2024-11-04 20:51:04,256 INFO: Microblog startup [in /home/sololobo/microblog/app/__init__.py:55]
2024-11-04 20:51:16,519 ERROR: Exception on /reset_password_request [POST] [in /home/sololobo/microblog/.venv/lib/python3.10/site-packages/flask/app.py:1414]
Traceback (most recent call last):
  File "/home/sololobo/microblog/.venv/lib/python3.10/site-packages/flask/app.py", line 2190, in wsgi_app
    response = self.full_dispatch_request()
  File "/home/sololobo/microblog/.venv/lib/python3.10/site-packages/flask/app.py", line 1486, in full_dispatch_request
    rv = self.handle_user_exception(e)
  File "/home/sololobo/microblog/.venv/lib/python3.10/site-packages/flask/app.py", line 1484, in full_dispatch_request
    rv = self.dispatch_request()
  File "/home/sololobo/microblog/.venv/lib/python3.10/site-packages/flask/app.py", line 1469, in dispatch_request
    return self.ensure_sync(self.view_functions[rule.endpoint])(**view_args)
  File "/home/sololobo/microblog/app/routes.py", line 214, in reset_password_request
    send_password_reset_email(user)
  File "/home/sololobo/microblog/app/email.py", line 14, in send_password_reset_email
    token = user.get_reset_password_token()
AttributeError: 'User' object has no attribute 'get_reset_password_token'
2024-11-04 21:23:29,941 INFO: Microblog startup [in /home/sololobo/microblog/app/__init__.py:55]
2024-11-04 21:23:37,775 ERROR: Exception on /reset_password_request [POST] [in /home/sololobo/microblog/.venv/lib/python3.10/site-packages/flask/app.py:1414]
Traceback (most recent call last):
  File "/home/sololobo/microblog/.venv/lib/python3.10/site-packages/flask/app.py", line 2190, in wsgi_app
    response = self.full_dispatch_request()
  File "/home/sololobo/microblog/.venv/lib/python3.10/site-packages/flask/app.py", line 1486, in full_dispatch_request
    rv = self.handle_user_exception(e)
  File "/home/sololobo/microblog/.venv/lib/python3.10/site-packages/flask/app.py", line 1484, in full_dispatch_request
    rv = self.dispatch_request()
  File "/home/sololobo/microblog/.venv/lib/python3.10/site-packages/flask/app.py", line 1469, in dispatch_request
    return self.ensure_sync(self.view_functions[rule.endpoint])(**view_args)
  File "/home/sololobo/microblog/app/routes.py", line 201, in reset_password_request
    send_password_reset_email(user)
  File "/home/sololobo/microblog/app/email.py", line 15, in send_password_reset_email
    token = user.get_reset_password_token()
AttributeError: 'User' object has no attribute 'get_reset_password_token'
2024-11-04 21:27:58,168 INFO: Microblog startup [in /home/sololobo/microblog/app/__init__.py:55]
2024-11-04 21:29:35,519 ERROR: Exception on /edit_profile [GET] [in /home/sololobo/microblog/.venv/lib/python3.10/site-packages/flask/app.py:1414]
Traceback (most recent call last):
  File "/home/sololobo/microblog/.venv/lib/python3.10/site-packages/flask/app.py", line 2190, in wsgi_app
    response = self.full_dispatch_request()
  File "/home/sololobo/microblog/.venv/lib/python3.10/site-packages/flask/app.py", line 1486, in full_dispatch_request
    rv = self.handle_user_exception(e)
  File "/home/sololobo/microblog/.venv/lib/python3.10/site-packages/flask/app.py", line 1484, in full_dispatch_request
    rv = self.dispatch_request()
  File "/home/sololobo/microblog/.venv/lib/python3.10/site-packages/flask/app.py", line 1469, in dispatch_request
    return self.ensure_sync(self.view_functions[rule.endpoint])(**view_args)
  File "/home/sololobo/microblog/.venv/lib/python3.10/site-packages/flask_login/utils.py", line 290, in decorated_view
    return current_app.ensure_sync(func)(*args, **kwargs)
  File "/home/sololobo/microblog/app/routes.py", line 123, in edit_profile
    form = EditProfileForm()
  File "/home/sololobo/microblog/.venv/lib/python3.10/site-packages/wtforms/form.py", line 208, in __call__
    return type.__call__(cls, *args, **kwargs)
TypeError: EditProfileForm.__init__() missing 1 required positional argument: 'original_username'
2024-11-04 21:36:38,324 INFO: Microblog startup [in /home/sololobo/microblog/app/__init__.py:55]
2024-11-04 21:39:30,163 INFO: Microblog startup [in /home/sololobo/microblog/app/__init__.py:45]
